=== Verificando conexão com o banco de dados ===
Psycopg2 está instalado, verificando conexão com PostgreSQL...
Tentativa 1/5...
Tentando conexão via DATABASE_URL: postgres:****@profilelink_banco:5432/profilelink?sslmode=disable
O host profilelink_banco é resolvível!
Conexão com o banco de dados bem-sucedida!
Versão do PostgreSQL: PostgreSQL 17.4 (Debian 17.4-1.pgdg120+2) on x86_64-pc-linux-gnu, compiled by gcc (Debian 12.2.0-14) 12.2.0, 64-bit
Teste de criação/acesso a tabelas bem-sucedido! (Total de testes: 470)
Todas as verificações passaram. Iniciando o servidor gunicorn...
===============================================
[2025-04-19 00:51:16 +0000] [7] [INFO] Starting gunicorn 21.2.0
[2025-04-19 00:51:16 +0000] [7] [INFO] Listening at: http://0.0.0.0:5000 (7)
[2025-04-19 00:51:16 +0000] [7] [INFO] Using worker: gthread
[2025-04-19 00:51:16 +0000] [11] [INFO] Booting worker with pid: 11
[2025-04-19 00:51:17 +0000] [12] [INFO] Booting worker with pid: 12
[2025-04-19 00:51:17 +0000] [13] [INFO] Booting worker with pid: 13
[2025-04-19 00:51:17 +0000] [14] [INFO] Booting worker with pid: 14
[2025-04-19 00:51:20 +0000] [11] [ERROR] Exception in worker process
Traceback (most recent call last):
  File "/usr/local/lib/python3.11/site-packages/gunicorn/arbiter.py", line 609, in spawn_worker
    worker.init_process()
  File "/usr/local/lib/python3.11/site-packages/gunicorn/workers/gthread.py", line 95, in init_process
    super().init_process()
  File "/usr/local/lib/python3.11/site-packages/gunicorn/workers/base.py", line 134, in init_process
    self.load_wsgi()
  File "/usr/local/lib/python3.11/site-packages/gunicorn/workers/base.py", line 146, in load_wsgi
    self.wsgi = self.app.wsgi()
                ^^^^^^^^^^^^^^^
  File "/usr/local/lib/python3.11/site-packages/gunicorn/app/base.py", line 67, in wsgi
    self.callable = self.load()
                    ^^^^^^^^^^^
  File "/usr/local/lib/python3.11/site-packages/gunicorn/app/wsgiapp.py", line 58, in load
    return self.load_wsgiapp()
           ^^^^^^^^^^^^^^^^^^^
  File "/usr/local/lib/python3.11/site-packages/gunicorn/app/wsgiapp.py", line 48, in load_wsgiapp
    return util.import_app(self.app_uri)
           ^^^^^^^^^^^^^^^^^^^^^^^^^^^^^
  File "/usr/local/lib/python3.11/site-packages/gunicorn/util.py", line 371, in import_app
    mod = importlib.import_module(module)
          ^^^^^^^^^^^^^^^^^^^^^^^^^^^^^^^
  File "/usr/local/lib/python3.11/importlib/__init__.py", line 126, in import_module
    return _bootstrap._gcd_import(name[level:], package, level)
           ^^^^^^^^^^^^^^^^^^^^^^^^^^^^^^^^^^^^^^^^^^^^^^^^^^^^
  File "<frozen importlib._bootstrap>", line 1204, in _gcd_import
  File "<frozen importlib._bootstrap>", line 1176, in _find_and_load
  File "<frozen importlib._bootstrap>", line 1147, in _find_and_load_unlocked
  File "<frozen importlib._bootstrap>", line 690, in _load_unlocked
  File "<frozen importlib._bootstrap_external>", line 940, in exec_module
  File "<frozen importlib._bootstrap>", line 241, in _call_with_frames_removed
  File "/app/main.py", line 2, in <module>
    from app import app  # noqa: F401
    ^^^^^^^^^^^^^^^^^^^
  File "/app/app.py", line 42, in <module>
    db.init_app(app)
  File "/usr/local/lib/python3.11/site-packages/flask_sqlalchemy/extension.py", line 374, in init_app
    engines[key] = self._make_engine(key, options, app)
                   ^^^^^^^^^^^^^^^^^^^^^^^^^^^^^^^^^^^^
  File "/usr/local/lib/python3.11/site-packages/flask_sqlalchemy/extension.py", line 665, in _make_engine
    return sa.engine_from_config(options, prefix="")
           ^^^^^^^^^^^^^^^^^^^^^^^^^^^^^^^^^^^^^^^^^
  File "/usr/local/lib/python3.11/site-packages/sqlalchemy/engine/create.py", line 823, in engine_from_config
    return create_engine(url, **options)
           ^^^^^^^^^^^^^^^^^^^^^^^^^^^^^
  File "<string>", line 2, in create_engine
  File "/usr/local/lib/python3.11/site-packages/sqlalchemy/util/deprecations.py", line 281, in warned
    return fn(*args, **kwargs)  # type: ignore[no-any-return]
           ^^^^^^^^^^^^^^^^^^^
  File "/usr/local/lib/python3.11/site-packages/sqlalchemy/engine/create.py", line 553, in create_engine
    entrypoint = u._get_entrypoint()
                 ^^^^^^^^^^^^^^^^^^^
  File "/usr/local/lib/python3.11/site-packages/sqlalchemy/engine/url.py", line 772, in _get_entrypoint
    cls = registry.load(name)
          ^^^^^^^^^^^^^^^^^^^
  File "/usr/local/lib/python3.11/site-packages/sqlalchemy/util/langhelpers.py", line 375, in load
    raise exc.NoSuchModuleError(
sqlalchemy.exc.NoSuchModuleError: Can't load plugin: sqlalchemy.dialects:postgres
[2025-04-19 00:51:20 +0000] [11] [INFO] Worker exiting (pid: 11)
[2025-04-19 00:51:20 +0000] [12] [ERROR] Exception in worker process
Traceback (most recent call last):
  File "/usr/local/lib/python3.11/site-packages/gunicorn/arbiter.py", line 609, in spawn_worker
    worker.init_process()
  File "/usr/local/lib/python3.11/site-packages/gunicorn/workers/gthread.py", line 95, in init_process
    super().init_process()
  File "/usr/local/lib/python3.11/site-packages/gunicorn/workers/base.py", line 134, in init_process
    self.load_wsgi()
  File "/usr/local/lib/python3.11/site-packages/gunicorn/workers/base.py", line 146, in load_wsgi
    self.wsgi = self.app.wsgi()